Workbook

Sheet Groupe
A1: ETU | B1: Prenom
A2: ETU003256 | B2: Fetraniaina
A3: ETU003287 | B3: Kasaina
A4: ETU003315 | B4: Tsiky
A5: ETU003326 | B5: Blessed

Sheet Todo
A1: Catégorie | B1: Module | C1: Pages | D1: Taches | E1: Type | F1: Qui | G1: Estimation | H1: Temps passes | I1: Reste a faire | J1: Avancement
A2: API, Mobile, Web | B2: Tiers | C2: No page | D2: Structure du projet | E2: Tier | F2: ETU003256 | G2: 15 | H2: =Details!B2 -> 15 | I2: 0 | J2: =(H2/(H2+I2))*100 -> 100
A3: API, Mobile, Web | B3: Tiers | C3: No page | D3: creation du repository | E3: Tier | F3: ETU003256 | G3: 8 | H3: =Details!B3 -> 10 | I3: 0 | J3: =(H3/(H3+I3))*100 -> 100
A4: API | B4: Tiers | C4: No page | D4: initialisation POSTGIS | E4: Base de donnee | F4: ETU003256 | G4: 10 | H4: =Details!B4 -> 15 | I4: 0 | J4: =(H4/(H4+I4))*100 -> 100
A5: API | B5: Login | C5: Admin/Login | D5: verification des identifiants | E5: Metier | F5: ETU003256 | G5: 9 | H5: =Details!B5 -> 15 | I5: 0 | J5: =(H5/(H5+I5))*100 -> 100
A6: API | B6: Login | C6: Admin/Login | D6: Generer le token JWT | E6: Metier | F6: ETU003256 | G6: 7 | H6: =Details!B6 -> 12 | I6: 0 | J6: =(H6/(H6+I6))*100 -> 100
A7: API | B7: Login | C7: Admin/Deblocage | D7: deblocage de l'utilisateur bloque par le manager | E7: Metier | F7: ETU003256 | G7: 15 | H7: =Details!B7 -> 10 | I7: 0 | J7: =(H7/(H7+I7))*100 -> 100
A8: API | B8: Duree Vie Session | C8: Admin/Login | D8: creation du middleware pour verifier l'expiration du token a chaque requette | E8: Metier | F8: ETU003256 | G8: 16 | H8: =Details!B8 -> 10 | I8: 0 | J8: =(H8/(H8+I8))*100 -> 100
A9: Web | B9: Tiers | C9: Global | D9: implementation du base service d'appel d'API | E9: Integration | F9: ETU003256 | G9: 8 | H9: =Details!B9 -> 15 | I9: 0 | J9: =(H9/(H9+I9))*100 -> 100
A10: Web | B10: Login | C10: Admin/Login | D10: page login et formulaire | E10: Affichage | F10: ETU003256 | G10: 5 | H10: =Details!B10 -> 15 | I10: 0 | J10: =(H10/(H10+I10))*100 -> 100
A11: Web | B11: Tableau Recapitualtion | C11: Web/Recapilation | D11: popup d'affichage de la racapitulation | E11: Affichage | F11: ETU003256 | G11: 15 | H11: =Details!B11 -> 10 | I11: 0 | J11: =(H11/(H11+I11))*100 -> 100
A12: Web | B12: Update Infos User | C12: Web/User | D12: Implementer l’appel API de mise a jour utilisateur | E12: Integration | F12: ETU003256 | G12: 10 | H12: =Details!B12 -> 11 | I12: 0 | J12: =(H12/(H12+I12))*100 -> 100
A13: Web, Mobile | B13: Synchronisation | C13: Global | D13: bouton : synchroniser | E13: Affichage | F13: ETU003256 | G13: 7 | H13: =Details!B13 -> 15 | I13: 0 | J13: =(H13/(H13+I13))*100 -> 100
... A113: Web | B113: Suivis probleme | C113: Web/Carte | D113: AJouter niveau dans les cartes | E113: Integration | F113: ETU003256 | G113: 5 | H113: =Details!B113 -> 5 | I113: 0 | J113: =(H113/(H113+I113))*100 -> 100

Sheet Details
A1: Todo Id | B1: Total | C1: 26/1 | D1: 27/1 | E1: 28/1 | F1: 2/2 | G1: 3/2 | H1: 6/2 | I1: 7/2 | J1: 9/2 | K1: 10/2
A2: 2 | B2: =sum(C2:Q2) -> 15 | C2: 15
A3: 3 | B3: =sum(C3:Q3) -> 10 | C3: 10
A4: 4 | B4: =sum(C4:Q4) -> 15 | C4: 15
A5: 5 | B5: =sum(C5:Q5) -> 15 | C5: 15 | P5: e
A6: 6 | B6: =sum(C6:Q6) -> 12 | C6: 12
A7: 7 | B7: =sum(C7:Q7) -> 10 | C7: 10
A8: 8 | B8: =sum(C8:Q8) -> 10 | C8: 10
A9: 9 | B9: =sum(C9:Q9) -> 15 | C9: 15
A10: 10 | B10: =sum(C10:Q10) -> 15 | C10: 15
A11: 11 | B11: =sum(C11:Q11) -> 10 | C11: 10
A12: 12 | B12: =sum(C12:Q12) -> 11 | C12: 11
A13: 13 | B13: =sum(C13:Q13) -> 15 | C13: 15
A14: 14 | B14: =sum(C14:Q14) -> 15 | C14: 15
A15: 15 | B15: =sum(C15:Q15) -> 15 | C15: 15
A16: 16 | B16: =sum(C16:Q16) -> 7 | C16: 7
A17: 17 | B17: =sum(C17:Q17) -> 6 | C17: 6
... A73: 73 | B73: =sum(C73:Q73) -> 25 | C73: 25
A74: 74 | B74: =sum(C74:Q74) -> 36 | C74: 16 | F74: 20
A75: 75 | B75: =sum(C75:Q75) -> 30 | D75: 10 | E75: 20
A76: 76 | B76: =sum(C76:Q76) -> 5 | G76: 5
A77: 77 | B77: =sum(C77:Q77) -> 15 | G77: 15
A78: 78 | B78: =sum(C78:Q78) -> 10 | G78: 10
A79: 79 | B79: =sum(C79:Q79) -> 10 | G79: 10
A80: 80 | B80: =sum(C80:Q80) -> 15 | G80: 15
A81: 81 | B81: =sum(C81:Q81) -> 10 | G81: 10
A82: 82 | B82: =sum(C82:Q82) -> 7 | G82: 7
A83: 83 | B83: =sum(C83:Q83) -> 8 | G83: 8
A84: 84 | B84: =sum(C84:Q84) -> 10 | G84: 10
A85: 85 | B85: =sum(C85:Q85) -> 15 | G85: 15
A86: 86 | B86: =sum(C86:Q86) -> 5 | G86: 5
A87: 87 | B87: =sum(C87:Q87) -> 15 | G87: 15
... A91: 91 | B91: =sum(C91:Q91) -> 7 | G91: 7
A92: 92 | B92: =sum(C92:Q92) -> 30 | G92: 5 | I92: 25
A93: 93 | B93: =sum(C93:Q93) -> 15 | G93: 15
A94: 94 | B94: =sum(C94:Q94) -> 8 | G94: 8
A95: 95 | B95: =sum(C95:Q95) -> 8 | G95: 8
A96: 96 | B96: =sum(C96:Q96) -> 5 | G96: 5
A97: 97 | B97: =sum(C97:Q97) -> 17 | G97: 10 | I97: 7
A98: 98 | B98: =sum(C98:Q98) -> 15 | G98: 10 | I98: 5
...

Sheet Recapitulation
A1: Qui | B1: Estimation | C1: Temps passer | D1: Avancement
A2: ETU003256 | B2: =SUMIF(TODO[Qui], A2, TODO[Estimation]) -> 369 | C2: =SUMIF(TODO[Qui], A2, TODO[Temps passes]) -> 401 | D2: =IFERROR(C2 /(C2 + SUMIF(TODO[Qui], A2, TODO[Reste a faire])),0)*100 -> 100
A3: ETU003287 | B3: =SUMIF(TODO[Qui], A3, TODO[Estimation]) -> 323 | C3: =SUMIF(TODO[Qui], A3, TODO[Temps passes]) -> 390 | D3: =IFERROR(C3 /(C3 + SUMIF(TODO[Qui], A3, TODO[Reste a faire])),0)*100 -> 100
A4: ETU003315 | B4: =SUMIF(TODO[Qui], A4, TODO[Estimation]) -> 341 | C4: =SUMIF(TODO[Qui], A4, TODO[Temps passes]) -> 391 | D4: =IFERROR(C4 /(C4 + SUMIF(TODO[Qui], A4, TODO[Reste a faire])),0)*100 -> 100
A5: ETU003326 | B5: =SUMIF(TODO[Qui], A5, TODO[Estimation]) -> 327 | C5: =SUMIF(TODO[Qui], A5, TODO[Temps passes]) -> 381 | D5: =IFERROR(C5 /(C5 + SUMIF(TODO[Qui], A5, TODO[Reste a faire])),0)*100 -> 100
A7: Total | B7: =sum(Recapitulation[Estimation]) -> 1360 | C7: =SUM(Recapitulation[Temps passer]) -> 1563 | D7: =SUM(Recapitulation[Avancement])/4 -> 100

Sheet Avancement
A1: Estimation Total | B1: Temps passer Total | C1: Reste a faire Total | D1: Avancement | E1: Depassement
A2: =SUM(TODO[Estimation]) -> 1360 | B2: =SUM(TODO[Temps passes]) -> 1563 | C2: =SUM(TODO[Reste a faire]) -> 0 | D2: =(B2/(B2+C2)) -> 1 | E2: =((B2+C2)-A2)/A2 -> 0.14926471
C4: =C2/60 -> 0 | D4: heure
